<?xml version="1.0" encoding="utf-8"?>
<!-- =================================================================================== -->
<!-- |    This document was autogenerated by xacro from robots/human_hand.urdf.xacro   | -->
<!-- |    EDITING THIS FILE BY HAND IS NOT RECOMMENDED                                 | -->
<!-- =================================================================================== -->
<robot name="human_hand">
  <!--
            HUMAN HAND MODEL v 0.1
            urdf derived from human Pisa SoftHand
            author Guillaume Walck, Robert Haschke
            meshes from GrabCAD, author Joerg Schmit
            original CAD model available at: https://grabcad.com/library/human-left-hand/
        -->
  <material name="HumanHand/Skin">
    <color rgba="0.802 0.732 0.673 1.0"/>
  </material>
  <link name="glove_base"/>
  <!-- PALM -->
  <joint name="palm_joint" type="revolute">
    <origin rpy="0 0 0" xyz="0 0 0"/>
    <parent link="glove_base"/>
    <child link="palm_link"/>
    <axis xyz="1 0 0"/>
    <limit effort="100" lower="-1.57079632679" upper="1.57079632679" velocity="100"/>
    <dynamics damping="0.0" friction="0.0"/>
  </joint>
  <link name="palm_link">
    <visual>
      <geometry>
        <mesh filename="palm.stl" scale="-0.003 0.003 0.003"/>
      </geometry>
      <material name="HumanHand/Skin"/>
    </visual>
  </link>
  <!-- THUMB AND FINGERS -->
  <!-- KNUCKLE -->
  <joint name="thumb_abduction_joint" type="revolute">
    <origin rpy="0.0 -0.624 0" xyz="-0.07425 -0.0375 0.0375"/>
    <parent link="palm_link"/>
    <child link="thumb_knuckle_link"/>
    <axis xyz="1 0 0"/>
    <limit effort="100" lower="0.0" upper="1.57079632679" velocity="100"/>
    <dynamics damping="0.0" friction="0.0"/>
  </joint>
  <link name="thumb_knuckle_link">
  </link>
  <!-- PROXIMAL PHALANGE -->
  <joint name="thumb_proximal_joint" type="revolute">
    <origin rpy="0 0 0" xyz="0 0 0"/>
    <parent link="thumb_knuckle_link"/>
    <child link="thumb_proximal_link"/>
    <axis xyz="0 1 0"/>
    <limit effort="100" lower="0.0" upper="1.57079632679" velocity="100"/>
    <dynamics damping="0.0" friction="0.0"/>
  </joint>
  <link name="thumb_proximal_link">
    <visual>
      <geometry>
        <mesh filename="thumb_proximal.stl" scale="-0.003 0.003 0.003"/>
      </geometry>
      <material name="HumanHand/Skin"/>
    </visual>
  </link>
  <!-- MIDDLE PHALANGE -->
  <joint name="thumb_middle_joint" type="revolute">
    <origin rpy="0 0 0" xyz="0 0 0.16245"/>
    <parent link="thumb_proximal_link"/>
    <child link="thumb_middle_link"/>
    <axis xyz="0 1 0"/>
    <limit effort="100" lower="0.0" upper="1.57079632679" velocity="100"/>
    <dynamics damping="0.0" friction="0.0"/>
  </joint>
  <link name="thumb_middle_link">
    <visual>
      <geometry>
        <mesh filename="thumb_middle.stl" scale="-0.003 0.003 0.003"/>
      </geometry>
      <material name="HumanHand/Skin"/>
    </visual>
  </link>
  <!-- DISTAL PHALANGE -->
  <joint name="thumb_distal_joint" type="revolute">
    <origin rpy="0 0 0" xyz="0 0 0.11409"/>
    <parent link="thumb_middle_link"/>
    <child link="thumb_distal_link"/>
    <axis xyz="0 1 0"/>
    <limit effort="100" lower="0.0" upper="1.57079632679" velocity="100"/>
    <dynamics damping="0.0" friction="0.0"/>
  </joint>
  <link name="thumb_distal_link">
    <visual>
      <geometry>
        <mesh filename="thumb_distal.stl" scale="-0.003 0.003 0.003"/>
      </geometry>
      <material name="HumanHand/Skin"/>
    </visual>
  </link>
  <!-- KNUCKLE -->
  <joint name="index_abduction_joint" type="revolute">
    <origin rpy="0 0 0" xyz="-0.06525 -0.006 0.297"/>
    <parent link="palm_link"/>
    <child link="index_knuckle_link"/>
    <axis xyz="0 1 0"/>
    <limit effort="100" lower="-0.523598775598" upper="0.523598775598" velocity="100"/>
    <dynamics damping="0.0" friction="0.0"/>
  </joint>
  <link name="index_knuckle_link">
  </link>
  <!-- PROXIMAL PHALANGE -->
  <joint name="index_proximal_joint" type="revolute">
    <origin rpy="0 0 0" xyz="0 0 0"/>
    <parent link="index_knuckle_link"/>
    <child link="index_proximal_link"/>
    <axis xyz="1 0 0"/>
    <limit effort="100" lower="0.0" upper="1.57079632679" velocity="100"/>
    <dynamics damping="0.0" friction="0.0"/>
  </joint>
  <link name="index_proximal_link">
    <visual>
      <geometry>
        <mesh filename="index_proximal.stl" scale="-0.003 0.003 0.003"/>
      </geometry>
      <material name="HumanHand/Skin"/>
    </visual>
  </link>
  <!-- MIDDLE PHALANGE -->
  <joint name="index_middle_joint" type="revolute">
    <origin rpy="0 0 0" xyz="0 0 0.138"/>
    <parent link="index_proximal_link"/>
    <child link="index_middle_link"/>
    <axis xyz="1 0 0"/>
    <limit effort="100" lower="0.0" upper="1.57079632679" velocity="100"/>
    <dynamics damping="0.0" friction="0.0"/>
  </joint>
  <link name="index_middle_link">
    <visual>
      <geometry>
        <mesh filename="index_middle.stl" scale="-0.003 0.003 0.003"/>
      </geometry>
      <material name="HumanHand/Skin"/>
    </visual>
  </link>
  <!-- DISTAL PHALANGE -->
  <joint name="index_distal_joint" type="revolute">
    <origin rpy="0 0 0" xyz="0 0 0.081"/>
    <parent link="index_middle_link"/>
    <child link="index_distal_link"/>
    <axis xyz="1 0 0"/>
    <limit effort="100" lower="0.0" upper="1.57079632679" velocity="100"/>
    <dynamics damping="0.0" friction="0.0"/>
  </joint>
  <link name="index_distal_link">
    <visual>
      <geometry>
        <mesh filename="index_distal.stl" scale="-0.003 0.003 0.003"/>
      </geometry>
      <material name="HumanHand/Skin"/>
    </visual>
  </link>
  <!-- KNUCKLE -->
  <joint name="middle_abduction_joint" type="revolute">
    <origin rpy="0 0 0" xyz="0.006 0.0045 0.2865"/>
    <parent link="palm_link"/>
    <child link="middle_knuckle_link"/>
    <axis xyz="0 1 0"/>
    <limit effort="100" lower="-0.523598775598" upper="0.523598775598" velocity="100"/>
    <dynamics damping="0.0" friction="0.0"/>
  </joint>
  <link name="middle_knuckle_link">
  </link>
  <!-- PROXIMAL PHALANGE -->
  <joint name="middle_proximal_joint" type="revolute">
    <origin rpy="0 0 0" xyz="0 0 0"/>
    <parent link="middle_knuckle_link"/>
    <child link="middle_proximal_link"/>
    <axis xyz="1 0 0"/>
    <limit effort="100" lower="0.0" upper="1.57079632679" velocity="100"/>
    <dynamics damping="0.0" friction="0.0"/>
  </joint>
  <link name="middle_proximal_link">
    <visual>
      <geometry>
        <mesh filename="middle_proximal.stl" scale="-0.003 0.003 0.003"/>
      </geometry>
      <material name="HumanHand/Skin"/>
    </visual>
  </link>
  <!-- MIDDLE PHALANGE -->
  <joint name="middle_middle_joint" type="revolute">
    <origin rpy="0 0 0" xyz="0 0 0.1485"/>
    <parent link="middle_proximal_link"/>
    <child link="middle_middle_link"/>
    <axis xyz="1 0 0"/>
    <limit effort="100" lower="0.0" upper="1.57079632679" velocity="100"/>
    <dynamics damping="0.0" friction="0.0"/>
  </joint>
  <link name="middle_middle_link">
    <visual>
      <geometry>
        <mesh filename="middle_middle.stl" scale="-0.003 0.003 0.003"/>
      </geometry>
      <material name="HumanHand/Skin"/>
    </visual>
  </link>
  <!-- DISTAL PHALANGE -->
  <joint name="middle_distal_joint" type="revolute">
    <origin rpy="0 0 0" xyz="0 0 0.099"/>
    <parent link="middle_middle_link"/>
    <child link="middle_distal_link"/>
    <axis xyz="1 0 0"/>
    <limit effort="100" lower="0.0" upper="1.57079632679" velocity="100"/>
    <dynamics damping="0.0" friction="0.0"/>
  </joint>
  <link name="middle_distal_link">
    <visual>
      <geometry>
        <mesh filename="middle_distal.stl" scale="-0.003 0.003 0.003"/>
      </geometry>
      <material name="HumanHand/Skin"/>
    </visual>
  </link>
  <!-- KNUCKLE -->
  <joint name="ring_abduction_joint" type="revolute">
    <origin rpy="0 0 0" xyz="0.06675 0.003 0.27"/>
    <parent link="palm_link"/>
    <child link="ring_knuckle_link"/>
    <axis xyz="0 1 0"/>
    <limit effort="100" lower="-0.523598775598" upper="0.523598775598" velocity="100"/>
    <dynamics damping="0.0" friction="0.0"/>
  </joint>
  <link name="ring_knuckle_link">
  </link>
  <!-- PROXIMAL PHALANGE -->
  <joint name="ring_proximal_joint" type="revolute">
    <origin rpy="0 0 0" xyz="0 0 0"/>
    <parent link="ring_knuckle_link"/>
    <child link="ring_proximal_link"/>
    <axis xyz="1 0 0"/>
    <limit effort="100" lower="0.0" upper="1.57079632679" velocity="100"/>
    <dynamics damping="0.0" friction="0.0"/>
  </joint>
  <link name="ring_proximal_link">
    <visual>
      <geometry>
        <mesh filename="ring_proximal.stl" scale="-0.003 0.003 0.003"/>
      </geometry>
      <material name="HumanHand/Skin"/>
    </visual>
  </link>
  <!-- MIDDLE PHALANGE -->
  <joint name="ring_middle_joint" type="revolute">
    <origin rpy="0 0 0" xyz="0 0 0.144"/>
    <parent link="ring_proximal_link"/>
    <child link="ring_middle_link"/>
    <axis xyz="1 0 0"/>
    <limit effort="100" lower="0.0" upper="1.57079632679" velocity="100"/>
    <dynamics damping="0.0" friction="0.0"/>
  </joint>
  <link name="ring_middle_link">
    <visual>
      <geometry>
        <mesh filename="ring_middle.stl" scale="-0.003 0.003 0.003"/>
      </geometry>
      <material name="HumanHand/Skin"/>
    </visual>
  </link>
  <!-- DISTAL PHALANGE -->
  <joint name="ring_distal_joint" type="revolute">
    <origin rpy="0 0 0" xyz="0 0 0.099"/>
    <parent link="ring_middle_link"/>
    <child link="ring_distal_link"/>
    <axis xyz="1 0 0"/>
    <limit effort="100" lower="0.0" upper="1.57079632679" velocity="100"/>
    <dynamics damping="0.0" friction="0.0"/>
  </joint>
  <link name="ring_distal_link">
    <visual>
      <geometry>
        <mesh filename="ring_distal.stl" scale="-0.003 0.003 0.003"/>
      </geometry>
      <material name="HumanHand/Skin"/>
    </visual>
  </link>
  <!-- KNUCKLE -->
  <joint name="little_abduction_joint" type="revolute">
    <origin rpy="0 0 0" xyz="0.12525 -0.009 0.237"/>
    <parent link="palm_link"/>
    <child link="little_knuckle_link"/>
    <axis xyz="0 1 0"/>
    <limit effort="100" lower="-0.523598775598" upper="0.523598775598" velocity="100"/>
    <dynamics damping="0.0" friction="0.0"/>
  </joint>
  <link name="little_knuckle_link">
  </link>
  <!-- PROXIMAL PHALANGE -->
  <joint name="little_proximal_joint" type="revolute">
    <origin rpy="0 0 0" xyz="0 0 0"/>
    <parent link="little_knuckle_link"/>
    <child link="little_proximal_link"/>
    <axis xyz="1 0 0"/>
    <limit effort="100" lower="0.0" upper="1.57079632679" velocity="100"/>
    <dynamics damping="0.0" friction="0.0"/>
  </joint>
  <link name="little_proximal_link">
    <visual>
      <geometry>
        <mesh filename="little_proximal.stl" scale="-0.003 0.003 0.003"/>
      </geometry>
      <material name="HumanHand/Skin"/>
    </visual>
  </link>
  <!-- MIDDLE PHALANGE -->
  <joint name="little_middle_joint" type="revolute">
    <origin rpy="0 0 0" xyz="0 0 0.111"/>
    <parent link="little_proximal_link"/>
    <child link="little_middle_link"/>
    <axis xyz="1 0 0"/>
    <limit effort="100" lower="0.0" upper="1.57079632679" velocity="100"/>
    <dynamics damping="0.0" friction="0.0"/>
  </joint>
  <link name="little_middle_link">
    <visual>
      <geometry>
        <mesh filename="little_middle.stl" scale="-0.003 0.003 0.003"/>
      </geometry>
      <material name="HumanHand/Skin"/>
    </visual>
  </link>
  <!-- DISTAL PHALANGE -->
  <joint name="little_distal_joint" type="revolute">
    <origin rpy="0 0 0" xyz="0 0 0.0645"/>
    <parent link="little_middle_link"/>
    <child link="little_distal_link"/>
    <axis xyz="1 0 0"/>
    <limit effort="100" lower="0.0" upper="1.57079632679" velocity="100"/>
    <dynamics damping="0.0" friction="0.0"/>
  </joint>
  <link name="little_distal_link">
    <visual>
      <geometry>
        <mesh filename="little_distal.stl" scale="-0.003 0.003 0.003"/>
      </geometry>
      <material name="HumanHand/Skin"/>
    </visual>
  </link>
  <!-- TACTILE MARKERS -->
</robot>